<?xml version="1.0"?>

<robot name="wheeled_inverted_pendulum">

        <link name="cmg">		    
		</link>

        <joint name="cmg_joint" type="fixed">
		    <origin xyz="0 0 1.114642" rpy="0.0 0.0 0.0" /> 
		    <parent link="cmg"/>
		    <child link="frame"/>
		</joint> 

        <link name="frame">
            <visual>
                <origin xyz="0 0 0" rpy="1.5708 0.0 0"/> <!--xyz="0.0 0.0 0.0" rpy="0 0.0 0" -->
                <geometry>
                    <mesh filename="package://cmg_robot_description/meshes/cmg_link.STL" scale="0.001 0.001 0.001"/>         
                </geometry>
                <material name=""/>
            </visual>

            <collision>
                <origin xyz="0 0 0" rpy="1.5708 0.0 0.0"/>
                <geometry>
                    <mesh filename="package://cmg_robot_description/meshes/cmg_link.STL" scale="0.001 0.001 0.001"/>
                </geometry>
            </collision>

            <inertial>
                <mass value="2.84" /> <!--20.781-->
                <origin xyz="0 0 -0.004142" rpy="1.5708 0.0 0"/>
                <inertia ixx="0.069831822" ixy="0.000002709"  ixz="0.001167158"  iyy="0.062838135"  iyz="0.000012214"  izz="0.037865996" />
            </inertial>
        </link>

<!-- ######################################################################################### -->

        <joint name="Left_gimbal_joint" type="revolute">
            <!-- <origin xyz="-0.000001 0.08 -0.0015" rpy="0 0 1.57"/> -->
            <origin xyz="0 0.08 0.00225" rpy="0 0 0"/>
            <axis xyz="0 0 1" />
            <parent link="frame"/>
            <child link="Left_gimbal"/>            
            <limit effort="100" velocity="100" upper="0.6978" lower="-0.6978"/>
            <!-- <calibration falling="1.0"/> -->
            <joint_properties damping="0.0" friction="0.0"/>
            <mimic joint="Right_gimbal_joint" multiplier="-1.0"/>

        </joint>

<!-- ######################################################################################### -->

        <link name="Left_gimbal">
            <visual>
                <origin xyz="0.0 0.0 0.0" rpy="1.57 0.0 0"/> 
                <geometry>
                    <mesh filename="package://cmg_robot_description/meshes/left_gimbal_link.STL" scale="0.001 0.001 0.001"/>         
                </geometry>
                <material name=""/>
            </visual>
            <collision>
                <origin xyz="0 0 0" rpy="1.57 0.0 0.0"/>
                <geometry>
                    <mesh filename="package://cmg_robot_description/meshes/left_gimbal_link.STL" scale="0.001 0.001 0.001"/>        
                </geometry>
            </collision>
            <inertial>
                <mass value="1" />
                <origin xyz="0 0 0" />
                <inertia ixx="0.003773117" ixy="0" ixz="0" iyy="0.003989672" iyz="0" izz="0.00061837"/>
            </inertial>
        </link>

<!-- ######################################################################################### -->

         <joint name="Left_flywheel_joint" type="continuous">
            <origin xyz="0 0 0" rpy="0 0 0"/>
            <axis xyz="0 1 0" />
            <parent link="Left_gimbal"/>
            <child link="Left_flywheel"/>
            <limit effort="100" velocity="1000"/>
            <joint_properties damping="0.0" friction="0.0"/>
            <mimic joint="Right_gimbal_joint" multiplier="-1.0"/>
        </joint>

<!-- ######################################################################################### -->

        <link name="Left_flywheel">
            <visual>
                <origin xyz="0 0 0" rpy="0 0 0" />
                <geometry>
                    <mesh filename="package://cmg_robot_description/meshes/left_flywheel_link.STL" scale="0.001 0.001 0.001" />
                </geometry>
                <material name=""/>
            </visual>

            <collision>
                <geometry>
                    <mesh filename="package://cmg_robot_description/meshes/left_flywheel_link.STL" scale="0.001 0.001 0.001" />
                </geometry>
            </collision>

            <inertial>
                <mass value="4" />
                <origin xyz="0 0 0" />
                <inertia ixx="0.005950" ixy="0" ixz="0" iyy="0.011299999" iyz="0" izz="0.005950"/>
            </inertial>
        </link>

<!-- ######################################################################################### -->

        <joint name="Right_gimbal_joint" type="revolute">            
            <origin xyz="0 -0.08 0.00225" rpy="0 0 0"/>
            <axis xyz="0 0 1" />
            <parent link="frame"/>
            <child link="Right_gimbal"/>            
            <limit effort="100" velocity="100" upper="0.6978" lower="-0.6978"/>
            <joint_properties damping="0.0" friction="0"/>
        </joint>

<!-- ######################################################################################### -->

        <link name="Right_gimbal">
            <visual>
                <origin xyz="0.0 0.0 0.0" rpy="1.57 0.0 0"/> 
                <geometry>
                    <mesh filename="package://cmg_robot_description/meshes/right_gimbal_link.STL" scale="0.001 0.001 0.001"/>         
                </geometry>
                <material name=""/>
            </visual>
            <collision>
                <origin xyz="0 0 0" rpy="1.57 0.0 0.0"/>
                <geometry>
                    <mesh filename="package://cmg_robot_description/meshes/right_gimbal_link.STL" scale="0.001 0.001 0.001"/>        
                </geometry>
            </collision>
            <inertial>
                <mass value="1" />
                <origin xyz="0 0 0" />
                <inertia ixx="0.003773117" ixy="0" ixz="0" iyy="0.003989672" iyz="0" izz="0.00061837"/>
            </inertial>
        </link>

<!-- ######################################################################################### -->

        <joint name="Right_flywheel_joint" type="continuous">
            <origin xyz="0 0 0" rpy="0 0 0"/>
            <axis xyz="0 1 0" />
            <parent link="Right_gimbal"/>
            <child link="Right_flywheel"/>
            <limit effort="100" velocity="1000"/>
            <joint_properties damping="0.0" friction="0.0"/>
        </joint>

<!-- ######################################################################################### -->

        <link name="Right_flywheel">
            <visual>
                <origin xyz="0 0 0" rpy="0 0 0" />
                <geometry>
                    <mesh filename="package://cmg_robot_description/meshes/right_flywheel_link.STL" scale="0.001 0.001 0.001" />
                </geometry>
                <material name=""/>
            </visual>

            <collision>
                <geometry>
                    <mesh filename="package://cmg_robot_description/meshes/right_flywheel_link.STL" scale="0.001 0.001 0.001" />
                </geometry>
            </collision>

            <inertial>
                <mass value="4" />
                <origin xyz="0 0 0" />
                <inertia ixx="0.005950" ixy="0" ixz="0" iyy="0.011299999" iyz="0" izz="0.005950"/>
            </inertial>
        </link>
        
<!-- ######################################################################################### -->
<!-- -0.220996 -->
        <joint name="hip_roll_joint" type="revolute">
            <origin xyz="0 0 -0.220996" rpy="0 0 0"/>
            <parent link="frame"/>
            <child link="hip_link"/>
            <axis xyz="1 0 0"/>
            <limit effort="100" velocity="1000" upper="0.785" lower="-0.785"/>
            <joint_properties damping="1.0" friction="1.0"/>
        </joint>

        <link name="hip_link">
            <visual>
                <origin xyz="-0.042455 0 0" rpy="3.14 0 0"/> 
                <geometry>
                    <mesh filename="package://cmg_robot_description/meshes/hip_link.STL" scale="0.001 0.001 0.001"/>         
                </geometry>
                <material name=""/>
            </visual>

            <collision>
                <origin xyz="-0.042455 0 0" rpy="3.14 0 0"/>
                <geometry>
                    <!-- <box size = "  0.127 0.168778 0.958442 "/>                     -->
                    <mesh filename="package://cmg_robot_description/meshes/hip_link.STL" scale="0.001 0.001 0.001"/>
                </geometry>
            </collision>

            <inertial>
                <mass value="3.325" /> 
                <origin xyz="0.0 0.0 0.011176" rpy="3.14 0.0 0"/>
                <inertia ixx="0.006208194" ixy="0.000396490"  ixz="-0.000685512"  iyy="0.006554912"  iyz="-0.000658520" izz="0.006773627" />
            </inertial>
        </link>

<!-- ######################################################################################### -->

        <joint name="hip_pitch_joint" type="fixed">
		    <!-- <origin xyz="0 -0.0045 -0.451221" rpy="0.0 0.0 0.0" />  -->
		    <origin xyz="0 0 0" rpy="0.0 0.0 0.0" /> 
            <!-- <axis xyz="0 1 0"/> -->
		    <parent link="hip_link"/>
		    <child link="hip_to_knee_link" />
            <!-- <limit effort="100" velocity="1000" upper="0.785" lower="-0.785"/>
            <joint_properties damping="1.0" friction="1.0"/> -->
		</joint> 

        <link name="hip_to_knee_link">
            <visual>
                <origin xyz="0.0 0.0665 0" rpy="3.14 0 0"/> 
                <geometry>
                    <mesh filename="package://cmg_robot_description/meshes/hip_to_knee_link.STL" scale="0.001 0.001 0.001"/>         
                </geometry>
                <material name=""/>
                    
            </visual>

            <collision>
                <origin xyz="0 0.0665 0.0" rpy="3.14 0 0"/>
                <geometry>
                    <!-- <box size = "  0.127 0.168778 0.958442 "/>                     -->
                    <mesh filename="package://cmg_robot_description/meshes/hip_to_knee_link.STL" scale="0.001 0.001 0.001"/>
                </geometry>
            </collision>

            <inertial>
                <mass value="2.175" /> 
                <origin xyz="0.0 0 -0.14958" rpy="3.14 0.0 0"/>
                <inertia ixx="0.007175717" ixy="0.000086944"  ixz="0.000249192"  iyy="0.006609551"  iyz="-0.000206119" izz="0.002458394" />
            </inertial>
        </link> 
<!-- ######################################################################################### -->

        <joint name="knee_joint" type="fixed">
		    <origin xyz="0 0 -0.28" rpy="0.0 0.0 0.0" /> 
            <!-- <axis xyz="0 1 0"/> -->
		    <parent link="hip_to_knee_link"/>
		    <child link="knee_ankle_link" />
            <!-- <limit effort="100" velocity="1000" upper="0.785" lower="-0.785"/>
            <joint_properties damping="1.0" friction="1.0"/> -->
		</joint> 

        <link name="knee_ankle_link">
            <visual>
                <origin xyz="0.000045 -0.059 0" rpy="3.14 0 0"/> 
                <geometry>
                    <mesh filename="package://cmg_robot_description/meshes/knee_to_ankle_pitch_link.STL" scale="0.001 0.001 0.001"/>         
                </geometry>
                <material name=""/>
                    
            </visual>

            <collision>
                <origin xyz="0.000045 -0.059 0" rpy="3.14 0 0"/>
                <geometry>
                    <!-- <box size = "  0.127 0.168778 0.958442 "/>                     -->
                    <mesh filename="package://cmg_robot_description/meshes/knee_to_ankle_pitch_link.STL" scale="0.001 0.001 0.001"/>
                </geometry>
            </collision>

            <inertial>
                <mass value="1.231" /> 
                <origin xyz="0.0 0 -0.12016" rpy="3.14 0.0 0"/>
                <inertia ixx="0.008859306" ixy="0.000111937"  ixz="0.000678647"  iyy="0.008343955"  iyz="-0.000413906" izz="0.002077894" />
            </inertial>
        </link> 
<!-- ######################################################################################### -->

        <joint name="ankle_pitch_joint" type="fixed">
		    <origin xyz="0 0 -0.279942" rpy="0.0 0.0 0.0" /> 
            <!-- <axis xyz="0 1 0"/> -->
		    <parent link="knee_ankle_link"/>
		    <child link="ankle_pitch_roll_link" />
            <!-- <limit effort="100" velocity="1000" upper="0.785" lower="-0.785"/>
            <joint_properties damping="1.0" friction="1.0"/> -->
		</joint> 

        <link name="ankle_pitch_roll_link">
            <visual>
                <origin xyz="0.0 0.0 0.0" rpy="3.14 0 0"/> 
                <geometry>
                    <mesh filename="package://cmg_robot_description/meshes/ankle_roll_link.STL" scale="0.001 0.001 0.001"/>         
                </geometry>
                <material name=""/>
                    
            </visual>

            <collision>
                <origin xyz="0 0 0" rpy="3.14 0 0"/>
                <geometry>
                    <!-- <box size = "  0.127 0.168778 0.958442 "/>                     -->
                    <mesh filename="package://cmg_robot_description/meshes/ankle_roll_link.STL" scale="0.001 0.001 0.001"/>
                </geometry>
            </collision>

            <inertial>
                <mass value="2.386" /> 
                <origin xyz="0.0 0.0 -0.0068274" rpy="3.14 0.0 0"/>
                <inertia ixx="0.003950987" ixy="0.000238179"  ixz="0.000315902"  iyy="0.004226334"  iyz="0.000351372" izz="0.004633548" />
            </inertial>
        </link> 

        
<!-- ######################################################################################### -->

        <joint name="ankle_roll_joint" type="revolute">
		    <!-- <origin xyz="0 -0.0045 -0.451221" rpy="0.0 0.0 0.0" />  -->
		    <origin xyz="0 0 0" rpy="0.0 0.0 0.0" /> 
            <axis xyz="1 0 0"/>
		    <parent link="ankle_pitch_roll_link"/>
		    <child link="ankle_roll_yaw_link" />
            <limit effort="100" velocity="1000" upper="0.785" lower="-0.785"/>
            <joint_properties damping="1.0" friction="1.0"/>
		</joint> 

        <link name="ankle_roll_yaw_link">
            <visual>
                <origin xyz="0.0825 0.0 0.0" rpy="3.14 0 0"/> 
                <geometry>
                    <mesh filename="package://cmg_robot_description/meshes/ankle_yaw_link.STL" scale="0.001 0.001 0.001"/>         
                </geometry>
                <material name=""/>
            </visual>

            <collision>
                <origin xyz="0.0825 0 0" rpy="3.14 0 0"/>
                <geometry>
                    <!-- <box size = "  0.127 0.168778 0.958442 "/>                     -->
                    <mesh filename="package://cmg_robot_description/meshes/ankle_yaw_link.STL" scale="0.001 0.001 0.001"/>
                </geometry>
            </collision>

            <inertial>
                <mass value="1.325" /> 
                <origin xyz="0.0 0.0 -0.093558" rpy="1.57 0 1.57"/>
                <inertia ixx="0.004491154" ixy="0.000005564"  ixz="0.000003285"  iyy="0.002633972"  iyz="0.000397982" izz="0.002356447" />
            </inertial>
        </link> 

<!-- ######################################################################################### -->

        <joint name="ankle_yaw_joint" type="fixed">
		    <!-- <origin xyz="0 -0.0045 -0.451221" rpy="0.0 0.0 0.0" />  -->
		    <origin xyz="0 0 -0.1675" rpy="0.0 0.0 0.0" /> 
            <!-- <axis xyz="0 0 1"/> -->
		    <parent link="ankle_roll_yaw_link"/>
		    <child link="ankle_to_wheel_link" />
            <!-- <limit effort="100" velocity="1000" upper="0.785" lower="-0.785"/> -->
            <!-- <joint_properties damping="1.0" friction="1.0"/> -->
		</joint> 

        <link name="ankle_to_wheel_link">
            <visual>
                <origin xyz="0.0 0.0 -0.09" rpy="0 0 0"/> 
                <geometry>
                    <mesh filename="package://cmg_robot_description/meshes/ankle_to_wheel_link.STL" scale="0.001 0.001 0.001"/>         
                </geometry>
                <material name=""/>
            </visual>

            <collision>
                <origin xyz="0 0 -0.09" rpy="0 0 0"/>
                <geometry>
                    <!-- <box size = "  0.127 0.168778 0.958442 "/>                     -->
                    <mesh filename="package://cmg_robot_description/meshes/ankle_to_wheel_link.STL" scale="0.001 0.001 0.001"/>
                </geometry>
            </collision>

            <inertial>
                <mass value="0.758" /> 
                <origin xyz="0 0 0" rpy="0.0 0.0 0"/>
                <inertia ixx="0.002298182" ixy="0.0"  ixz="0.0"  iyy="0.001121639"  iyz="-0.0" izz="0.001482959" />
            </inertial>
        </link>

<!-- ######################################################################################### -->

        <joint name="wheel_joint" type="continuous">
		    <!-- <origin xyz="0 -0.0045 -0.451221" rpy="0.0 0.0 0.0" />  -->
		    <origin xyz="0 0 -0.09" rpy="0.0 0.0 0.0" /> 
            <axis xyz="0 1 0"/>
		    <parent link="ankle_to_wheel_link"/>
		    <child link="wheel_link" />
            <limit effort="100" velocity="1000"/>
            <joint_properties damping="1.0" friction="1.0"/>
		</joint>

         <link name="wheel_link">
            <visual>
                <origin xyz="0.0 0.0 0.0" rpy="0 0.0 1.57"/> 
                <geometry>
                    <mesh filename="package://cmg_robot_description/meshes/wheel_link.STL" scale="0.001 0.001 0.001"/>         
                </geometry>
                <material name=""/>
            </visual>

            <collision>                
                <origin xyz="0 0 0" rpy="0 0.0 1.57"/>
                <geometry>
                    <mesh filename="package://cmg_robot_description/meshes/wheel_link.STL" scale="0.001 0.001 0.001"/>                 
                </geometry>
            </collision>

            <inertial>
                <mass value="2.0" />
                <origin xyz="0 0 0" />
                <inertia ixx="0.003623375" ixy="0.0" ixz="0.0" iyy="0.006512625" iyz="0.0" izz="0.003623375"/>
            </inertial>
        </link> 

<!-- ######################################################################################### -->

        <gazebo reference="frame">
            <mu1>1.0</mu1>
            <mu2>1.0</mu2> 
            <kp>1e+13</kp>
            <kd>1.0</kd>
            <maxVel>0.001</maxVel>
            <minDepth>0.00000000001</minDepth>
            <gravity>1</gravity>
            <material>Gazebo/Grey</material>
            <!-- <selfCollide>true</selfCollide> -->
        </gazebo>

        <gazebo reference="Left_gimbal">
            <mu1>1.0</mu1>
            <mu2>1.0</mu2> 
            <kp>1e+13</kp>
            <kd>1.0</kd>
            <maxVel>0.001</maxVel>
            <minDepth>0.00000000001</minDepth>
            <gravity>1</gravity>
            <material>Gazebo/Grey</material>
            <selfCollide>true</selfCollide>
        </gazebo>

        <gazebo reference="Left_flywheel">
            <mu1>1.0</mu1>
            <mu2>1.0</mu2> 
            <kp>1e+13</kp>
            <kd>1.0</kd>
            <maxVel>0.001</maxVel>
            <minDepth>0.00000000001</minDepth>
            <gravity>1</gravity>
            <material>Gazebo/White</material>
        </gazebo>


        <gazebo reference="Right_gimbal">
            <mu1>1.0</mu1>
            <mu2>1.0</mu2> 
            <kp>1e+13</kp>
            <kd>1.0</kd>
            <maxVel>0.001</maxVel>
            <minDepth>0.00000000001</minDepth>
            <gravity>1</gravity>
            <material>Gazebo/Grey</material>
            <selfCollide>true</selfCollide>
        </gazebo>

        <gazebo reference="Right_flywheel">
            <mu1>1.0</mu1>
            <mu2>1.0</mu2> 
            <kp>1e+13</kp>
            <kd>1.0</kd>
            <maxVel>0.001</maxVel>
            <minDepth>0.00000000001</minDepth>
            <gravity>1</gravity>
            <material>Gazebo/White</material>
        </gazebo>


<!-- ######################################################################################### -->

        <gazebo reference="hip_link">
            <mu1>1.0</mu1>
            <mu2>1.0</mu2> 
            <kp>1e+13</kp>
            <kd>1.0</kd>
            <maxVel>0.001</maxVel>
            <minDepth>0.00000000001</minDepth>
            <gravity>1</gravity>
            <material>Gazebo/Grey</material>
        </gazebo>

        <gazebo reference="hip_to_knee_link">
            <mu1>1.0</mu1>
            <mu2>1.0</mu2> 
            <kp>1e+13</kp>
            <kd>1.0</kd>
            <maxVel>0.001</maxVel>
            <minDepth>0.00000000001</minDepth>
            <gravity>1</gravity>
            <material>Gazebo/Grey</material>
        </gazebo>

        <gazebo reference="knee_ankle_link">
            <mu1>1.0</mu1>
            <mu2>1.0</mu2> 
            <kp>1e+13</kp>
            <kd>1.0</kd>
            <maxVel>0.001</maxVel>
            <minDepth>0.00000000001</minDepth>
            <gravity>1</gravity>
            <material>Gazebo/Grey</material>
        </gazebo>

        <gazebo reference="ankle_pitch_roll_link">
            <mu1>1.0</mu1>
            <mu2>1.0</mu2> 
            <kp>1e+13</kp>
            <kd>1.0</kd>
            <maxVel>0.001</maxVel>
            <minDepth>0.00000000001</minDepth>
            <gravity>1</gravity>
            <material>Gazebo/Grey</material>
        </gazebo>

        <gazebo reference="ankle_roll_yaw_link">
            <mu1>1.0</mu1>
            <mu2>1.0</mu2> 
            <kp>1e+13</kp>
            <kd>1.0</kd>
            <maxVel>0.001</maxVel>
            <minDepth>0.00000000001</minDepth>
            <gravity>1</gravity>
            <material>Gazebo/Grey</material>
        </gazebo>

        <gazebo reference="ankle_to_wheel_link">
            <mu1>1.0</mu1>
            <mu2>1.0</mu2> 
            <kp>1e+13</kp>
            <kd>1.0</kd>
            <maxVel>0.001</maxVel>
            <minDepth>0.00000000001</minDepth>
            <gravity>1</gravity>
            <material>Gazebo/Grey</material>
        </gazebo>

        <gazebo reference="wheel_link">
            <collision name="wheel_collision">
                <surface>
                    <friction>
                        <torsional>
                            <coefficient>1</coefficient>
                            <use_patch_radius>true</use_patch_radius>
                            <patch_radius>0.02</patch_radius>
                        </torsional>
                    </friction>
                </surface>
            </collision>
            <mu1>1.0</mu1>
            <mu2>1.0</mu2> 
            <kp>1e+13</kp>
            <kd>1.0</kd>
            <maxVel>0.001</maxVel>
            <minDepth>0.00000000001</minDepth>
            <gravity>1</gravity>
            <material>Gazebo/White</material>
        </gazebo>


<!-- ######################################################################################### -->

        <gazebo>
            <plugin name="gazebo_ros_control" filename="libgazebo_ros_control.so">
                <controlPeriod>0.001</controlPeriod>
                <robotNamespace>/wheeled_inverted_pendulum</robotNamespace>
                <!-- <jointName> Right_gimbal_joint, Left_gimbal_joint, Left_flywheel_joint, Right_flywheel_joint, hip_roll_joint, hip_pitch_joint, knee_joint, ankle_pitch_joint, ankle_roll_joint, wheel_joint </jointName> -->
                <robotSimType>gazebo_ros_control/DefaultRobotHWSim</robotSimType>
                <legacyModeNS>true</legacyModeNS>
            </plugin>
        </gazebo>

        <gazebo>
            <plugin name="mimic_control" filename="libroboticsgroup_upatras_gazebo_mimic_joint_plugin.so">
                <joint>Right_gimbal_joint</joint>
                <mimicJoint>Left_gimbal_joint</mimicJoint>
                <multiplier>-1.0</multiplier>
                <!-- <hasPID>/gazebo_ros_control/pid_gains/Left_gimbal_joint</hasPID> -->
                <!-- /gazebo_ros_control/pid_gains/Left_gimbal_joint -->
            </plugin>
        </gazebo>

        <transmission name="Left_flywheel_trans">
            <type>transmission_interface/SimpleTransmission</type>
            <joint name="Left_flywheel_joint" >
                <hardwareInterface>hardware_interface/VelocityJointInterface</hardwareInterface>
            </joint>
            <actuator name="Left_flywheel_motor">
                <hardwareInterface>hardware_interface/VelocityJointInterface</hardwareInterface>
                <mechanicalReduction>1</mechanicalReduction>
            </actuator>
        </transmission>

        <!-- <transmission name="Left_gimbal_trans">
            <type>transmission_interface/SimpleTransmission</type>
            <joint name="Left_gimbal_joint" >
                <hardwareInterface>hardware_interface/EffortJointInterface</hardwareInterface>
            </joint>
            <actuator name="Left_gimbal_motor">
                <hardwareInterface>hardware_interface/EffortJointInterface</hardwareInterface>
                <mechanicalReduction>1</mechanicalReduction>
            </actuator>
        </transmission> -->


        <transmission name="Right_flywheel_trans">
            <type>transmission_interface/SimpleTransmission</type>
            <joint name="Right_flywheel_joint" >
                <hardwareInterface>hardware_interface/VelocityJointInterface</hardwareInterface>
            </joint>
            <actuator name="Right_flywheel_motor">
                <hardwareInterface>hardware_interface/VelocityJointInterface</hardwareInterface>
                <mechanicalReduction>1</mechanicalReduction>
            </actuator>
        </transmission>

        <transmission name="Right_gimbal_trans">
            <type>transmission_interface/SimpleTransmission</type>
            <joint name="Right_gimbal_joint" >
                <hardwareInterface>hardware_interface/EffortJointInterface</hardwareInterface>
            </joint>
            <actuator name="Right_gimbal_motor">
                <hardwareInterface>hardware_interface/EffortJointInterface</hardwareInterface>
                <mechanicalReduction>1</mechanicalReduction>
            </actuator>
        </transmission>

<!-- ######################################################################################### -->

        <transmission name="hip_roll_trans">
            <type>transmission_interface/SimpleTransmission</type>
            <joint name="hip_roll_joint" >
                <hardwareInterface>hardware_interface/PositionJointInterface</hardwareInterface>
            </joint>
            <actuator name="hip_roll_motor">
                <hardwareInterface>hardware_interface/PositionJointInterface</hardwareInterface>
                <mechanicalReduction>1</mechanicalReduction>
            </actuator>
        </transmission>

        <!-- <transmission name="hip_pitch_trans">
            <type>transmission_interface/SimpleTransmission</type>
            <joint name="hip_pitch_joint" >
                <hardwareInterface>hardware_interface/PositionJointInterface</hardwareInterface>
            </joint>
            <actuator name="hip_pitch_motor">
                <hardwareInterface>hardware_interface/PositionJointInterface</hardwareInterface>
                <mechanicalReduction>1</mechanicalReduction>
            </actuator>
        </transmission>


        <transmission name="knee_trans">
            <type>transmission_interface/SimpleTransmission</type>
            <joint name="knee_joint" >
                <hardwareInterface>hardware_interface/PositionJointInterface</hardwareInterface>
            </joint>
            <actuator name="knee_motor">
                <hardwareInterface>hardware_interface/PositionJointInterface</hardwareInterface>
                <mechanicalReduction>1</mechanicalReduction>
            </actuator>
        </transmission>

        <transmission name="ankle_pitch_trans">
            <type>transmission_interface/SimpleTransmission</type>
            <joint name="ankle_pitch_joint" >
                <hardwareInterface>hardware_interface/PositionJointInterface</hardwareInterface>
            </joint>
            <actuator name="ankle_pitch_motor">
                <hardwareInterface>hardware_interface/PositionJointInterface</hardwareInterface>
                <mechanicalReduction>1</mechanicalReduction>
            </actuator>
        </transmission> -->

        <transmission name="ankle_roll_trans">
            <type>transmission_interface/SimpleTransmission</type>
            <joint name="ankle_roll_joint" >
                <hardwareInterface>hardware_interface/PositionJointInterface</hardwareInterface>
            </joint>
            <actuator name="ankle_roll_motor">
                <hardwareInterface>hardware_interface/PositionJointInterface</hardwareInterface>
                <mechanicalReduction>1</mechanicalReduction>
            </actuator>
        </transmission>

        <!-- <transmission name="ankle_yaw_trans">
            <type>transmission_interface/SimpleTransmission</type>
            <joint name="ankle_yaw_joint" >
                <hardwareInterface>hardware_interface/PositionJointInterface</hardwareInterface>
            </joint>
            <actuator name="ankle_yaw_motor">
                <hardwareInterface>hardware_interface/PositionJointInterface</hardwareInterface>
                <mechanicalReduction>1</mechanicalReduction>
            </actuator>
        </transmission> -->

        <transmission name="wheel_trans">
            <type>transmission_interface/SimpleTransmission</type>
            <joint name="wheel_joint" >
                <hardwareInterface>hardware_interface/EffortJointInterface</hardwareInterface>
            </joint>
            <actuator name="wheel_motor">
                <hardwareInterface>hardware_interface/EffortJointInterface</hardwareInterface>
                <mechanicalReduction>1</mechanicalReduction>
            </actuator>
        </transmission>

<!-- EffortJointInterface
PositionJointInterface
VelocityJointInterface -->

</robot>